Workbook
Name \T: #REF!
Name _01_01_99: #REF!
Name _01_02_99: #REF!
Name _01_03_99: #REF!
Name _01_04_99: #REF!
Name _01_05_99: #REF!
Name _01_06_99: #REF!
Name _01_07_99: #REF!
Name _01_08_1999: #REF!
Name _01_11_2001: #N/A
Name _1: #REF!
Name _10000: #REF!
Name _1000A01: #N/A
Name _10TRÒ_GIAÙ: #REF!
Name _11TRÒ_GIAÙ__VAT: #REF!
Name _1Index: 1
Name _2: #REF!
Name _2MAÕ_HAØNG: #REF!
Name _3: #REF!
Name _3MAÕ_SOÁ_THUEÁ: #REF!
Name _4ÑÔN_GIAÙ: #REF!
Name _5SOÁ_CTÖØ: #REF!
Name _6SOÁ_LÖÔÏNG: #REF!
Name _7TEÂN_HAØNG: #REF!
Name _8TEÂN_KHAÙCH_HAØ: #REF!
Name _9THAØNH_TIEÀN: #REF!
Name _atn1: #REF!
Name _atn10: #REF!
Name _atn2: #REF!
Name _atn3: #REF!
Name _atn4: #REF!
Name _atn5: #REF!
Name _atn6: #REF!
Name _atn7: #REF!
Name _atn8: #REF!
Name _atn9: #REF!
Name _blm12: #REF!
Name _blm16: #REF!
Name _blm18: #REF!
Name _blm20: #REF!
Name _boi1: #REF!
Name _boi2: #REF!
Name _boi3: #REF!
Name _boi4: #REF!
Name _btm10: #REF!
Name _btm100: #REF!
Name _BTM150: #REF!
Name _BTM250: #REF!
Name _btM300: #REF!
Name _BTM50: #REF!
Name _Cau2: #REF!
Name _CON1: #REF!
Name _CON2: #REF!
Name _cpd1: #REF!
Name _cpd2: #REF!
Name _CT250: #REF!
Name _dao1: #REF!
Name _dbu1: #REF!
Name _dbu2: #REF!
Name _ddn400: #REF!

Sheet TTKQ
B1: PHIẾU TƯ VẤN TÍNH GIÁ CĂN HỘ "IMPERIA SKY PARK" (THAM KHẢO)
B2: Lưu ý: -Phiếu tư vấn này chỉ mang tính chất tham khảo. Các thông tin dưới đây không phải là thông tin chính thức từ Chủ đầu tư và không có giá trị pháp lý. Vui lòng tham khảo kỹ thông tin về điều kiện áp dụng đối với từng chương trình ưu đãi, chiết khấu tại Chính sách bán hàng & các văn bản liên quan. - Mọi ưu đãi, chiết khấu chỉ được áp dụng khi Người Mua ký HĐMB & thanh toán tương ứng theo Tiến độ thanh toán theo Chính sách bán hàng.
B4: I | C4: THÔNG TIN CĂN HỘ
B5: 1 | C5: Mã căn hộ | I5: S2.3108 | K5: << Nhập mã căn
B6: 2 | C6: Dự án | I6: Imperia Sky Park
B7: 3 | C7: Toà | I7: =LEFT(I5,2) -> S2
B8: 4 | C8: Tầng | I8: 12
B9: 5 | C9: Căn số | I9: =RIGHT(I5,IF(OR(RIGHT(I5,1)="A",RIGHT(I5,1)="B"),3,2)) -> 08
B10: 6 | C10: Diện tích thông thủy (m2) | K10: << Nhập diện tích thông thuỷ theo bảng hàng
B11: 7 | C11: Loại căn | K11: << Nhập theo thông tin bảng hàng
B12: II | C12: GIÁ BÁN NIÊM YẾT | F12: BÀN GIAO KHÔNG GIAN SÁNG TẠO
C13: Giá bán (chưa gồm VAT) | I13: 9424447600 | K13: << Nhập giá bán chưa VAT
C14: Thuế VAT | I14: =I15-I13 -> 942444760
C15: Giá bán (gồm VAT, chưa gồm KPBT) | I15: 10366892360 | K15: << Nhập giá bán gồm VAT, chưa KPBT
C16: Kinh phí bảo trì | I16: =ROUND(2%*I13,0) -> 188488952
C17: Giá bán (gồm VAT và KPBT) | I17: =I15+I16 -> 10555381312
B18: III | C18: GIÁ BÁN SAU ƯU ĐÃI
B19: a | C19: Có ký TTKQ hay không? | I19: Y | K19: << Chọn "Y" = là có vào TTKQ, chọn N giai đoạn ko áp dụng TTKQ nữa
B20: b | C20: Tổng Chiết khấu ưu đãi | I20: =I22+I21 -> -4.3564967e+08
C21: Chiết khấu ưu đãi cho khách không nhận BLNH | E21: Khách lựa chọn BLNH | F21: N | H21: =IF(F21="N",0.7%,0%) -> 0.007 | I21: =-H21*I13 -> -65971133 | K21: << Chọn "Y" = nhận BLNH; Chọn "N" = từ chối BLNH
C22: b.1 Chiết khấu ưu đãi theo CSKD / TTKQ | I22: =SUM(I23:I27) -> -369678537
C23: Quà tặng “Signature Privilege” | H23: 0.02 | I23: =-ROUND(H23*SUM(I$13,$I$21),0) -> -187169529 | K23: << Nhập theo CSBH, số âm (-) nếu là số tuyệt đối
C24: Quà tặng “Frontage Privilege” - S3 | H24: 0.01 | I24: =-ROUND(H24*SUM(I$13,I$23:I23,$I$21),0) -> -91713069 | K24: << Nhập theo CSBH, số âm (-) nếu là số tuyệt đối
C25: Quà tặng “An Phúc Phú Quý”- E1, S1, S2 | K25: << Nhập theo CSBH, số âm (-) nếu là số tuyệt đối
C26: Quà tặng “Elite Privilege” | H26: 0.01 | I26: =-ROUND(H26*SUM(I$13,I$23:I25,$I$21),0) -> -90795939 | K26: << Nhập theo CSBH, số âm (-) nếu là số tuyệt đối
C27: Chiết khấu ưu đãi khác 3 (nếu có) | I27: =-ROUND(H27*SUM(I$13,I$23:I26,$I$21),0) -> 0 | K27: << Nhập theo CSBH, số âm (-) nếu là số tuyệt đối
C28: Giá cơ sở (chưa gồm VAT) | I28: =I13+I20 -> 8.9887979e+09
C29: Thuế VAT | I29: =ROUND(I14+I20*10%,0) -> 898879793
C30: Giá cơ sở (gồm VAT, chưa bao gồm KPBT) | I30: =I28+I29 -> 9.8876777e+09
C31: Kinh phí bảo trì | I31: =ROUND(I28*2%,0) -> 179775959
C32: Giá cơ sở (gồm VAT & KPBT) | I32: =I30+I31 -> 1.0067454e+10
B33: IV | C33: TIẾN ĐỘ THANH TOÁN THỎA THUẬN KÝ QUỸ ('TTKQ')
B34: ĐỢT | C34: Tiến độ thanh toán | H34: Tổng Số tiền (VNĐ)
B35: 1 | C35: Khi ký TTKQ | I35: 100000000
B36: 2 | C36: Trong vòng 7 ngày kể từ ngày ký TTKQ | H36: 0.1 | I36: =ROUND(H36*I$30,0)-I35 -> 888767772
B37: 3 | C37: =IF(F26="Y","Trong vòng 30 ngày kể từ ngày ký TTKQ","Chậm nhất vào ngày 15/07/2026") -> Chậm nhất vào ngày 15/07/2026 | H37: 0.05 | I37: =ROUND(H37*I$30,0) -> 494383886
B38: Tổng cộng | H38: =I38/I30 -> 0.15 | I38: =SUM(I35:I37) -> 1483151658

Sheet TT Chuẩn
B1: PHIẾU TƯ VẤN TÍNH GIÁ CĂN HỘ "IMPERIA SMART CITY" (THAM KHẢO)
B2: Lưu ý: -Phiếu tư vấn này chỉ mang tính chất tham khảo. Các thông tin dưới đây không phải là thông tin chính thức từ Chủ đầu tư và không có giá trị pháp lý. Vui lòng tham khảo kỹ thông tin về điều kiện áp dụng đối với từng chương trình ưu đãi, chiết khấu tại Chính sách bán hàng & các văn bản liên quan. - Mọi ưu đãi, chiết khấu chỉ được áp dụng khi Người Mua ký HĐMB & thanh toán tương ứng theo Tiến độ thanh toán theo Chính sách bán hàng.
B4: I | C4: THÔNG TIN CĂN HỘ
B5: 1 | C5: Mã căn hộ | I5: =TTKQ!I5 -> S2.3108 | K5: << Nhập mã căn
B6: 2 | C6: Dự án | I6: =TTKQ!I6 -> Imperia Sky Park
B7: 3 | C7: Toà | I7: =TTKQ!I7 -> S2
B8: 4 | C8: Tầng | I8: =TTKQ!I8 -> 12
B9: 5 | C9: Căn số | I9: =TTKQ!I9 -> 08
B10: 6 | C10: Diện tích thông thủy (m2) | I10: =TTKQ!I10 -> 0 | K10: << Nhập diện tích thông thuỷ theo bảng hàng
B11: 7 | C11: Loại căn | I11: =TTKQ!I11 -> 0 | K11: << Nhập theo thông tin bảng hàng
B12: II | C12: GIÁ BÁN NIÊM YẾT | D12: =TTKQ!$F$12 -> BÀN GIAO KHÔNG GIAN SÁNG TẠO
C13: Giá bán (chưa gồm VAT) | I13: =TTKQ!I13 -> 9424447600 | K13: << Nhập giá bán chưa VAT
C14: Thuế VAT | I14: =TTKQ!I14 -> 942444760
C15: Giá bán (gồm VAT, chưa gồm KPBT) | I15: =TTKQ!I15 -> 10366892360 | K15: << Nhập giá bán gồm VAT, chưa KPBT
C16: Kinh phí bảo trì | I16: =TTKQ!I16 -> 188488952
C17: Giá bán (gồm VAT và KPBT) | I17: =TTKQ!I17 -> 10555381312
B18: III | C18: GIÁ BÁN SAU ƯU ĐÃI
B19: a | C19: Tiến độ thanh toán lựa chọn | I19: Thanh toán chuẩn
B20: b | C20: Chiết khấu ưu đãi | I20: =I22+I28+I21 -> -4.3564967e+08 | N20: =I20-TTKQ!I20 -> 0
C21: Chiết khấu ưu đãi cho khách không nhận BLNH | H21: =TTKQ!H21 -> 0.007 | I21: =-H21*I13 -> -65971133 | K21: << Chọn "Y" = nhận BLNH; Chọn "N" = từ chối BLNH | N21: =I21-TTKQ!I21 -> 0
C22: b.1 Chiết khấu ưu đãi theo CSBH | I22: =SUM(I23:I27) -> -369678537 | N22: =I22-TTKQ!I22 -> 0
C23: =TTKQ!C23 -> Quà tặng “Signature Privilege” | H23: =TTKQ!H23 -> 0.02 | I23: =-ROUND(H23*SUM(I$13,$I$21),0) -> -187169529 | K23: << Nhập theo CSBH, số âm (-) | N23: =I23-TTKQ!I23 -> 0
C24: =TTKQ!C24 -> Quà tặng “Frontage Privilege” - S3 | H24: =TTKQ!H24 -> 0.01 | I24: =-ROUND(H24*SUM(I$13,I$23:I23,$I$21),0) -> -91713069 | K24: << Nhập theo CSBH | N24: =I24-TTKQ!I24 -> 0
C25: =TTKQ!C25 -> Quà tặng “An Phúc Phú Quý”- E1, S1, S2 | I25: =TTKQ!$I$25 -> 0 | K25: << Nhập theo CSBH
C26: =TTKQ!C26 -> Quà tặng “Elite Privilege” | H26: =TTKQ!H26 -> 0.01 | I26: =-ROUND(H26*SUM(I$13,I$23:I25,$I$21),0) -> -90795939 | K26: << Nhập theo CSBH | N26: =I26-TTKQ!I26 -> 0
C27: =TTKQ!C27 -> Chiết khấu ưu đãi khác 3 (nếu có) | H27: =TTKQ!H27 -> 0 | I27: =TTKQ!I27 -> 0 | K27: << Nhập theo CSBH | N27: =I27-TTKQ!I27 -> 0
C28: b.2 Chiết khấu ưu đãi theo lựa chọn tiến độ thanh toán thanh toán | H28: 0 | I28: =-ROUND(H28*SUM(I$13,I$23:I27,$I$21),0) -> 0 | K28: << Nhập % CK theo CSBH
C29: Giá bán sau ưu đãi (chưa gồm VAT) | I29: =I13+I20 -> 8.9887979e+09 | K29: =I29/TTKQ!I28-1 -> 0
C30: Thuế VAT | I30: =ROUND(I14+I20*10%,0) -> 898879793 | K30: =I30/TTKQ!I29-1 -> 0
C31: Giá bán sau ưu đãi (gồm VAT, chưa bao gồm KPBT) | I31: =I29+I30 -> 9.8876777e+09 | K31: =I31/TTKQ!I30-1 -> 0
C32: Kinh phí bảo trì | I32: =ROUND(I29*2%,0) -> 179775959 | K32: =I32/TTKQ!I31-1 -> 0
C33: Giá bán sau ưu đãi (gồm VAT & KPBT) | I33: =I31+I32 -> 1.0067454e+10 | K33: =I33/TTKQ!I32-1 -> 0
B34: IV | C34: TIẾN ĐỘ THANH TOÁN HỢP ĐỒNG MUA BÁN ('HĐMB')
B35: ĐỢT | C35: Tiến độ thanh toán | H35: Tổng Số tiền (VNĐ)
C36: ĐẶT CỌC | I36: =IF(TTKQ!$I$19="Y",0,100000000) -> 0
B37: 1 | C37: Ký HĐMB (Trong vòng 07 ngày làm việc kể từ ngày thanh toán đủ tiền đặt cọc) | H37: 0.2 | I37: =ROUND(H37*I$31,0)-I36 -> 1977535545 | K37: Đóng thêm so với TTKQ | L37: =IF(TTKQ!$I$19="Y",I37-TTKQ!$I$38,I37) -> 494383887
B38: 2 | C38: Trong vòng 30 ngày kể từ ngày ký HĐMB | H38: 0.05 | I38: =ROUND(H38*I$31,0) -> 494383886
B39: 3 | C39: Chậm nhất vào ngày 15/12/2026 | H39: 0.05 | I39: =ROUND(H39*I$31,0) -> 494383886
B40: 4 | C40: Chậm nhất vào ngày 15/03/2027 | H40: 0.05 | I40: =IF(LEFT(C40,8)="Bàn giao",I$33-SUM(#REF!,I$37,I$39:I39),ROUND(H40*I$31,0)) -> 494383886
B41: 5 | C41: Chậm nhất vào ngày 15/06/2027 | H41: 0.05 | I41: =IF(LEFT(C41,8)="Bàn giao",I$33-SUM(#REF!,I$37,I$39:I40),ROUND(H41*I$31,0)) -> 494383886
...

Sheet TTS 95%
B1: PHIẾU TƯ VẤN TÍNH GIÁ CĂN HỘ "IMPERIA SMART CITY" (THAM KHẢO)
B2: Lưu ý: -Phiếu tư vấn này chỉ mang tính chất tham khảo. Các thông tin dưới đây không phải là thông tin chính thức từ Chủ đầu tư và không có giá trị pháp lý. Vui lòng tham khảo kỹ thông tin về điều kiện áp dụng đối với từng chương trình ưu đãi, chiết khấu tại Chính sách bán hàng & các văn bản liên quan. - Mọi ưu đãi, chiết khấu chỉ được áp dụng khi Người Mua ký HĐMB & thanh toán tương ứng theo Tiến độ thanh toán theo Chính sách bán hàng.
B4: I | C4: THÔNG TIN CĂN HỘ
B5: 1 | C5: Mã căn hộ | I5: =TTKQ!I5 -> S2.3108 | K5: << Nhập ở sheet "TT Chuẩn", dữ liệu tự đồng bộ
B6: 2 | C6: Dự án | I6: =TTKQ!I6 -> Imperia Sky Park | K6: << Nhập ở sheet "TT Chuẩn", dữ liệu tự đồng bộ
B7: 3 | C7: Toà | I7: =TTKQ!I7 -> S2 | K7: << Nhập ở sheet "TT Chuẩn", dữ liệu tự đồng bộ
B8: 4 | C8: Tầng | I8: =TTKQ!I8 -> 12 | K8: << Nhập ở sheet "TT Chuẩn", dữ liệu tự đồng bộ
B9: 5 | C9: Căn số | I9: =TTKQ!I9 -> 08 | K9: << Nhập ở sheet "TT Chuẩn", dữ liệu tự đồng bộ
B10: 6 | C10: Diện tích thông thủy (m2) | I10: =TTKQ!I10 -> 0 | K10: << Nhập ở sheet "TT Chuẩn", dữ liệu tự đồng bộ
B11: 7 | C11: Loại căn | I11: =TTKQ!I11 -> 0 | K11: << Nhập ở sheet "TT Chuẩn", dữ liệu tự đồng bộ
B12: II | C12: GIÁ BÁN NIÊM YẾT
C13: Giá bán (chưa gồm VAT) | I13: =TTKQ!I13 -> 9424447600 | K13: << Nhập ở sheet "TT Chuẩn", dữ liệu tự đồng bộ
C14: Thuế VAT | I14: =TTKQ!I14 -> 942444760 | K14: << Nhập ở sheet "TT Chuẩn", dữ liệu tự đồng bộ
C15: Giá bán (gồm VAT, chưa gồm KPBT) | I15: =TTKQ!I15 -> 10366892360 | K15: << Nhập ở sheet "TT Chuẩn", dữ liệu tự đồng bộ
C16: Kinh phí bảo trì | I16: =TTKQ!I16 -> 188488952 | K16: << Nhập ở sheet "TT Chuẩn", dữ liệu tự đồng bộ
C17: Giá bán (gồm VAT và KPBT) | I17: =TTKQ!I17 -> 10555381312 | K17: << Nhập ở sheet "TT Chuẩn", dữ liệu tự đồng bộ
B18: III | C18: GIÁ BÁN SAU ƯU ĐÃI
B19: a | C19: Tiến độ thanh toán lựa chọn | I19: Thanh toán sớm nhận Chiết khấu
B20: b | C20: Chiết khấu ưu đãi | I20: =I22+I28+I21 -> -1.3345295e+09 | N20: =I20-TTKQ!I20 -> -898879793
C21: Chiết khấu ưu đãi cho khách không nhận BLNH | H21: =TTKQ!H21 -> 0.007 | I21: =-H21*I13 -> -65971133 | K21: << Chọn "Y" = nhận BLNH; Chọn "N" = từ chối BLNH | N21: =I21-TTKQ!I21 -> 0
C22: b.1 Chiết khấu ưu đãi theo CSBH | I22: =SUM(I23:I27) -> -369678537 | N22: =I22-TTKQ!I22 -> 0
C23: =TTKQ!C23 -> Quà tặng “Signature Privilege” | H23: =TTKQ!H23 -> 0.02 | I23: =-ROUND(H23*SUM(I$13,$I$21),0) -> -187169529 | K23: << Nhập ở sheet "TT Chuẩn", dữ liệu tự đồng bộ | N23: =I23-TTKQ!I23 -> 0
C24: =TTKQ!C24 -> Quà tặng “Frontage Privilege” - S3 | H24: =TTKQ!H24 -> 0.01 | I24: =-ROUND(H24*SUM(I$13,I$23:I23,$I$21),0) -> -91713069 | K24: << Nhập ở sheet "TT Chuẩn", dữ liệu tự đồng bộ | N24: =I24-TTKQ!I24 -> 0
C25: =TTKQ!C25 -> Quà tặng “An Phúc Phú Quý”- E1, S1, S2 | I25: =TTKQ!$I$25 -> 0
C26: =TTKQ!C26 -> Quà tặng “Elite Privilege” | H26: =TTKQ!H26 -> 0.01 | I26: =-ROUND(H26*SUM(I$13,I$23:I25,$I$21),0) -> -90795939 | K26: << Nhập theo CSBH | N26: =I26-TTKQ!I26 -> 0
C27: =TTKQ!C27 -> Chiết khấu ưu đãi khác 3 (nếu có) | H27: =TTKQ!H27 -> 0 | I27: =TTKQ!I27 -> 0 | K27: << Nhập theo CSBH | N27: =I27-TTKQ!I27 -> 0
C28: b.2 Chiết khấu thanh toán của tiến độ | H28: 0.1 | I28: =-ROUND(H28*SUM(I$13,I$23:I27,$I$21),0) -> -898879793 | K28: << Nhập % CK theo CSBH
C29: Giá bán sau ưu đãi (chưa gồm VAT) | I29: =I13+I20 -> 8.0899181e+09 | K29: =I29/TTKQ!I28-1 -> -0.1 | M29: =I29/I13-1 -> -0.14160294
C30: Thuế VAT | I30: =ROUND(I14+(I20-I28)*10%,0) -> 898879793 | K30: =I30/TTKQ!I29-1 -> 0 | M30: =I30/I14-1 -> -0.046225486
C31: Giá bán sau ưu đãi (gồm VAT, chưa bao gồm KPBT) | I31: =I29+I30 -> 8.9887979e+09 | K31: =I31/TTKQ!I30-1 -> -0.090909091 | M31: =I31/I15-1 -> -0.13293226
C32: Kinh phí bảo trì | I32: =ROUND((I29-I28)*2%,0) -> 179775959 | K32: =I32/TTKQ!I31-1 -> 0 | M32: =I32/I16-1 -> -0.046225484
C33: Giá bán sau ưu đãi (gồm VAT & KPBT) | I33: =I31+I32 -> 9.1685739e+09 | K33: =I33/TTKQ!I32-1 -> -0.089285714 | M33: =I33/I17-1 -> -0.13138392
B34: IV | C34: TIẾN ĐỘ THANH TOÁN HỢP ĐỒNG MUA BÁN ('HĐMB')
B35: ĐỢT | C35: Tiến độ thanh toán | H35: Tổng Số tiền (VNĐ)
C36: ĐẶT CỌC | I36: =IF(TTKQ!$I$19="Y",0,100000000) -> 0
B37: 1 | C37: Ký HĐMB (Trong vòng 07 ngày làm việc kể từ ngày thanh toán đủ tiền đặt cọc) | H37: 0.2 | I37: =ROUND(H37*I$31,0)-I36 -> 1797759586 | K37: Đóng thêm so với TTKQ | M37: =IF(TTKQ!$I$19="Y",I37-TTKQ!$I$38,I37) -> 314607928
B38: 2 | C38: Trong vòng 30 ngày kể từ ngày ký HĐMB | H38: 0.75 | I38: =ROUND(H38*I$31,0) -> 6741598447
B39: 3 | C39: ='TT Chuẩn'!C46 -> Bàn giao căn hộ (dự kiến tháng 9/2028) | H39: 0.05 | I39: =IF(LEFT(C39,8)="Bàn giao",I$33-SUM(I$36,I$37,I$38:I38),ROUND(H39*I$31,0)) -> 6.2921586e+08
B40: Tổng cộng | H40: =SUM(H37:H39) -> 1 | I40: =SUM(I38:I39,I37,I36) -> 9.1685739e+09

Sheet TT sớm nhận HTLS 70%
B1: PHIẾU TƯ VẤN TÍNH GIÁ CĂN HỘ "IMPERIA SKY PARK" (THAM KHẢO)
B2: Lưu ý: -Phiếu tư vấn này chỉ mang tính chất tham khảo. Các thông tin dưới đây không phải là thông tin chính thức từ Chủ đầu tư và không có giá trị pháp lý. Vui lòng tham khảo kỹ thông tin về điều kiện áp dụng đối với từng chương trình ưu đãi, chiết khấu tại Chính sách bán hàng & các văn bản liên quan. - Mọi ưu đãi, chiết khấu chỉ được áp dụng khi Người Mua ký HĐMB & thanh toán tương ứng theo Tiến độ thanh toán theo Chính sách bán hàng.
B4: I | C4: THÔNG TIN CĂN HỘ
B5: 1 | C5: Mã căn hộ | I5: =TTKQ!I5 -> S2.3108 | K5: << Nhập ở sheet "TT Chuẩn", dữ liệu tự đồng bộ
B6: 2 | C6: Dự án | I6: =TTKQ!I6 -> Imperia Sky Park | K6: << Nhập ở sheet "TT Chuẩn", dữ liệu tự đồng bộ
B7: 3 | C7: Toà | I7: =TTKQ!I7 -> S2 | K7: << Nhập ở sheet "TT Chuẩn", dữ liệu tự đồng bộ
B8: 4 | C8: Tầng | I8: =TTKQ!I8 -> 12 | K8: << Nhập ở sheet "TT Chuẩn", dữ liệu tự đồng bộ
B9: 5 | C9: Căn số | I9: =TTKQ!I9 -> 08 | K9: << Nhập ở sheet "TT Chuẩn", dữ liệu tự đồng bộ
B10: 6 | C10: Diện tích thông thủy (m2) | I10: =TTKQ!I10 -> 0 | K10: << Nhập ở sheet "TT Chuẩn", dữ liệu tự đồng bộ
B11: 7 | C11: Loại căn | I11: =TTKQ!I11 -> 0 | K11: << Nhập ở sheet "TT Chuẩn", dữ liệu tự đồng bộ
B12: II | C12: GIÁ BÁN NIÊM YẾT
C13: Giá bán (chưa gồm VAT) | I13: =TTKQ!I13 -> 9424447600 | K13: << Nhập ở sheet "TT Chuẩn", dữ liệu tự đồng bộ | N13: =I13-TTKQ!I13 -> 0
C14: Thuế VAT | I14: =ROUND(TTKQ!I14+(I13-TTKQ!I13)*10%,0) -> 942444760 | K14: << Nhập ở sheet "TT Chuẩn", dữ liệu tự đồng bộ | N14: =I14-TTKQ!I14 -> 0
C15: Giá bán (gồm VAT, chưa gồm KPBT) | I15: =I13+I14 -> 10366892360 | K15: << Nhập ở sheet "TT Chuẩn", dữ liệu tự đồng bộ | N15: =I15-TTKQ!I15 -> 0
C16: Kinh phí bảo trì | I16: =ROUND(I13*2%,0) -> 188488952 | K16: << Nhập ở sheet "TT Chuẩn", dữ liệu tự đồng bộ | N16: =I16-TTKQ!I16 -> 0
C17: Giá bán (gồm VAT và KPBT) | I17: =I15+I16 -> 10555381312 | K17: << Nhập ở sheet "TT Chuẩn", dữ liệu tự đồng bộ | N17: =I17-TTKQ!I17 -> 0
B18: III | C18: GIÁ BÁN SAU ƯU ĐÃI
B19: a | C19: Tiến độ thanh toán lựa chọn | I19: HTLS 0% tối đa 70% GTCH trong 24 tháng
I20: Lựa chọn 1
B21: b | C21: TỔNG CHIẾT KHẤU ƯU ĐÃI | I21: =I23+I29+I22 -> -4.3564967e+08 | N21: =I21-TTKQ!I20 -> 0
C22: Chiết khấu ưu đãi cho khách không nhận BLNH | H22: =TTKQ!H21 -> 0.007 | I22: =-H22*I13 -> -65971133 | K22: << Chọn "Y" = nhận BLNH; Chọn "N" = từ chối BLNH | N22: =I22-TTKQ!I21 -> 0
C23: b.1 Chiết khấu ưu đãi theo CSBH | I23: =SUM(I24:I28) -> -369678537 | N23: =I23-TTKQ!I22 -> 0
C24: =TTKQ!C23 -> Quà tặng “Signature Privilege” | H24: =TTKQ!H23 -> 0.02 | I24: =-ROUND(H24*SUM(I$13,$I$22),0) -> -187169529 | K24: << Nhập ở sheet "TT Chuẩn", dữ liệu tự đồng bộ | N24: =I24-TTKQ!I23 -> 0
C25: =TTKQ!C24 -> Quà tặng “Frontage Privilege” - S3 | H25: =TTKQ!H24 -> 0.01 | I25: =-ROUND(H25*SUM(I$13,I$24:I24,$I$22),0) -> -91713069 | K25: << Nhập ở sheet "TT Chuẩn", dữ liệu tự đồng bộ | N25: =I25-TTKQ!I24 -> 0
C26: =TTKQ!C25 -> Quà tặng “An Phúc Phú Quý”- E1, S1, S2 | I26: =TTKQ!$I$25 -> 0
C27: =TTKQ!C26 -> Quà tặng “Elite Privilege” | H27: =TTKQ!H26 -> 0.01 | I27: =-ROUND(H27*SUM(I$13,I$24:I26,$I$22),0) -> -90795939 | K27: << Nhập theo CSBH | N27: =I27-TTKQ!I26 -> 0
C28: =TTKQ!C27 -> Chiết khấu ưu đãi khác 3 (nếu có) | H28: =TTKQ!H27 -> 0 | I28: =TTKQ!I27 -> 0 | K28: << Nhập theo CSBH | N28: =I28-TTKQ!I27 -> 0
C29: b.2 Chiết khấu ưu đãi theo lựa chọn tiến độ thanh toán thanh toán (nếu có) | H29: 0 | I29: =ROUND(H29*SUM(I$13,I$24:I28,$I$22),0) -> 0 | K29: << Nhập % CK theo CSBH
B30: c | C30: Điều chỉnh Tăng giá theo tiến độ | H30: 0.06 | I30: =ROUND(H30*SUM(I$13,I$24:I29,$I$22),0) -> 539327876 | K30: << Nhập % CK theo CSBH
B31: d.1 | C31: Ưu đãi nhận Hỗ trợ lãi suất 0%
C32: Thời hạn hỗ trợ | E32: 24 tháng kể từ ngày giải ngân đầu tiên
C33: Lãi suất áp dụng trong thời gian hỗ trợ | I33: 0
C34: Gốc vay tối đa được hỗ trợ lãi suất | E34: 70% Giá trị Căn hộ trên HĐMB (gồm VAT, không gồm KPBT)
B35: d.2 | C35: Ưu đãi bảo đảm lãi suất (nếu có)
C36: Thời hạn hỗ trợ | E36: =IF($I$20="Lựa chọn 2","24 tháng kể từ ngày kết thúc HTLS 0%","")
C37: Lãi suất áp dụng trong thời gian hỗ trợ | I37: =IF($I$20="Lựa chọn 2","Lãi suất khách phải trả không lớn hơn 6,8%/năm","")
C38: Gốc vay tối đa được hỗ trợ | E38: =IF($I$20="Lựa chọn 2","Theo dự nợ thực tế (tối đa bằng giá trị khoản vay đã được HTLS 0%)","")
C39: Giá bán sau ưu đãi (chưa gồm VAT) | I39: =I13+I21+I30 -> 9.5281258e+09
C40: Thuế VAT | I40: =ROUND(I14+(I21+I30)*10%,0) -> 952812581
C41: Giá bán sau ưu đãi (gồm VAT, chưa bao gồm KPBT) | I41: =I39+I40 -> 1.0480938e+10
...
